<robot
  name="model8">
  <link
    name="base_link">
    <inertial>
      <origin
        xyz="0 0.0196398440124442 0.03"
        rpy="0 0 0" />
      <mass
        value="0.11815581103802" />
      <inertia
        ixx="9.51506167926554E-06"
        ixy="9.66785018978693E-21"
        ixz="2.28782652689305E-13"
        iyy="2.64453255573571E-06"
        iyz="8.47032947254294E-22"
        izz="6.87052912352988E-06" />
    </inertial>
    <visual>
      <origin
        xyz="0 0 0"
        rpy="0 0 0" />
      <geometry>
        <mesh
          filename="package://model8/meshes/base_link.STL" />
      </geometry>
      <material
        name="">
        <color
          rgba="0.752941176470588 0.752941176470588 0.752941176470588 1" />
      </material>
    </visual>
    <collision>
      <origin
        xyz="0 0 0"
        rpy="0 0 0" />
      <geometry>
        <mesh
          filename="package://model8/meshes/base_link.STL" />
      </geometry>
    </collision>
  </link>
  <link
    name="M1">
    <inertial>
      <origin
        xyz="-2.90113099377098E-08 0.0234550125674209 0.0300000000000001"
        rpy="0 0 0" />
      <mass
        value="0.0968618745655004" />
      <inertia
        ixx="1.57938620308465E-05"
        ixy="-3.85313324699336E-11"
        ixz="2.28782649902332E-13"
        iyy="2.64453255590243E-06"
        iyz="-2.3083938980612E-20"
        izz="1.31493294752775E-05" />
    </inertial>
    <visual>
      <origin
        xyz="0 0 0"
        rpy="0 0 0" />
      <geometry>
        <mesh
          filename="package://model8/meshes/M1.STL" />
      </geometry>
      <material
        name="">
        <color
          rgba="0.752941176470588 0.752941176470588 0.752941176470588 1" />
      </material>
    </visual>
    <collision>
      <origin
        xyz="0 0 0"
        rpy="0 0 0" />
      <geometry>
        <mesh
          filename="package://model8/meshes/M1.STL" />
      </geometry>
    </collision>
  </link>
  <joint
    name="J1"
    type="revolute">
    <origin
      xyz="0 0.080147 0"
      rpy="-5.445E-16 -7.3829E-16 3.6937E-16" />
    <parent
      link="base_link" />
    <child
      link="M1" />
    <axis
      xyz="0 0 1" />
    <limit
      lower="-1.571"
      upper="1.571"
      effort="0"
      velocity="0" />
  </joint>
  <link
    name="M2">
    <inertial>
      <origin
        xyz="-2.90113099515876E-08 0.0234550125674209 0.03"
        rpy="0 0 0" />
      <mass
        value="0.0968618745655004" />
      <inertia
        ixx="1.57938620308465E-05"
        ixy="-3.85313324650622E-11"
        ixz="2.28782651787835E-13"
        iyy="2.64453255590242E-06"
        iyz="-4.63773623227938E-20"
        izz="1.31493294752775E-05" />
    </inertial>
    <visual>
      <origin
        xyz="0 0 0"
        rpy="0 0 0" />
      <geometry>
        <mesh
          filename="package://model8/meshes/M2.STL" />
      </geometry>
      <material
        name="">
        <color
          rgba="0.752941176470588 0.752941176470588 0.752941176470588 1" />
      </material>
    </visual>
    <collision>
      <origin
        xyz="0 0 0"
        rpy="0 0 0" />
      <geometry>
        <mesh
          filename="package://model8/meshes/M2.STL" />
      </geometry>
    </collision>
  </link>
  <joint
    name="J2"
    type="revolute">
    <origin
      xyz="0 0.082647 0"
      rpy="0 4.4896E-16 -2.7711E-17" />
    <parent
      link="M1" />
    <child
      link="M2" />
    <axis
      xyz="0 0 1" />
    <limit
      lower="-1.571"
      upper="1.571"
      effort="0"
      velocity="0" />
  </joint>
  <link
    name="M3">
    <inertial>
      <origin
        xyz="-2.90113099515876E-08 0.0234550125674209 0.03"
        rpy="0 0 0" />
      <mass
        value="0.0968618745655004" />
      <inertia
        ixx="1.57938620308465E-05"
        ixy="-3.85313324719697E-11"
        ixz="2.28782654140448E-13"
        iyy="2.64453255590243E-06"
        iyz="-2.12836106898012E-20"
        izz="1.31493294752775E-05" />
    </inertial>
    <visual>
      <origin
        xyz="0 0 0"
        rpy="0 0 0" />
      <geometry>
        <mesh
          filename="package://model8/meshes/M3.STL" />
      </geometry>
      <material
        name="">
        <color
          rgba="0.752941176470588 0.752941176470588 0.752941176470588 1" />
      </material>
    </visual>
    <collision>
      <origin
        xyz="0 0 0"
        rpy="0 0 0" />
      <geometry>
        <mesh
          filename="package://model8/meshes/M3.STL" />
      </geometry>
    </collision>
  </link>
  <joint
    name="J3"
    type="revolute">
    <origin
      xyz="0 0.082647 0"
      rpy="9.0749E-17 -2.4669E-16 -9.0749E-17" />
    <parent
      link="M2" />
    <child
      link="M3" />
    <axis
      xyz="0 0 1" />
    <limit
      lower="-1.571"
      upper="1.571"
      effort="0"
      velocity="0" />
  </joint>
  <link
    name="M4">
    <inertial>
      <origin
        xyz="-2.90113099238321E-08 0.023455012567421 0.03"
        rpy="0 0 0" />
      <mass
        value="0.0968618745655006" />
      <inertia
        ixx="1.57938620308465E-05"
        ixy="-3.853133246773E-11"
        ixz="2.28782654646005E-13"
        iyy="2.64453255590244E-06"
        iyz="-4.250237930801E-22"
        izz="1.31493294752775E-05" />
    </inertial>
    <visual>
      <origin
        xyz="0 0 0"
        rpy="0 0 0" />
      <geometry>
        <mesh
          filename="package://model8/meshes/M4.STL" />
      </geometry>
      <material
        name="">
        <color
          rgba="0.752941176470588 0.752941176470588 0.752941176470588 1" />
      </material>
    </visual>
    <collision>
      <origin
        xyz="0 0 0"
        rpy="0 0 0" />
      <geometry>
        <mesh
          filename="package://model8/meshes/M4.STL" />
      </geometry>
    </collision>
  </link>
  <joint
    name="J4"
    type="revolute">
    <origin
      xyz="0 0.082647 0"
      rpy="9.0749E-17 -2.4669E-16 -9.0749E-17" />
    <parent
      link="M3" />
    <child
      link="M4" />
    <axis
      xyz="0 0 1" />
    <limit
      lower="-1.571"
      upper="1.571"
      effort="0"
      velocity="0" />
  </joint>
  <link
    name="M5">
    <inertial>
      <origin
        xyz="-2.90113098960765E-08 0.023455012567421 0.03"
        rpy="0 0 0" />
      <mass
        value="0.0968618745655006" />
      <inertia
        ixx="1.57938620308465E-05"
        ixy="-3.85313324751812E-11"
        ixz="2.28782651866568E-13"
        iyy="2.64453255590243E-06"
        iyz="-1.23276250185249E-21"
        izz="1.31493294752775E-05" />
    </inertial>
    <visual>
      <origin
        xyz="0 0 0"
        rpy="0 0 0" />
      <geometry>
        <mesh
          filename="package://model8/meshes/M5.STL" />
      </geometry>
      <material
        name="">
        <color
          rgba="0.752941176470588 0.752941176470588 0.752941176470588 1" />
      </material>
    </visual>
    <collision>
      <origin
        xyz="0 0 0"
        rpy="0 0 0" />
      <geometry>
        <mesh
          filename="package://model8/meshes/M5.STL" />
      </geometry>
    </collision>
  </link>
  <joint
    name="J5"
    type="revolute">
    <origin
      xyz="0 0.082647 0"
      rpy="8.4372E-17 -3.5974E-16 8.4372E-17" />
    <parent
      link="M4" />
    <child
      link="M5" />
    <axis
      xyz="0 0 1" />
    <limit
      lower="-1.571"
      upper="1.571"
      effort="0"
      velocity="0" />
  </joint>
  <link
    name="M6">
    <inertial>
      <origin
        xyz="-2.90113099238321E-08 0.0234550125674209 0.0299999999999998"
        rpy="0 0 0" />
      <mass
        value="0.0968618745655006" />
      <inertia
        ixx="1.57938620308465E-05"
        ixy="-3.85313324809194E-11"
        ixz="2.28782653052666E-13"
        iyy="2.64453255590243E-06"
        iyz="-3.09181815818711E-20"
        izz="1.31493294752776E-05" />
    </inertial>
    <visual>
      <origin
        xyz="0 0 0"
        rpy="0 0 0" />
      <geometry>
        <mesh
          filename="package://model8/meshes/M6.STL" />
      </geometry>
      <material
        name="">
        <color
          rgba="0.752941176470588 0.752941176470588 0.752941176470588 1" />
      </material>
    </visual>
    <collision>
      <origin
        xyz="0 0 0"
        rpy="0 0 0" />
      <geometry>
        <mesh
          filename="package://model8/meshes/M6.STL" />
      </geometry>
    </collision>
  </link>
  <joint
    name="J6"
    type="revolute">
    <origin
      xyz="0 0.082647 0"
      rpy="-8.4372E-17 -3.7505E-16 -8.4372E-17" />
    <parent
      link="M5" />
    <child
      link="M6" />
    <axis
      xyz="0 0 1" />
    <limit
      lower="-1.571"
      upper="1.571"
      effort="0"
      velocity="0" />
  </joint>
  <link
    name="M7">
    <inertial>
      <origin
        xyz="-2.90113099238321E-08 0.0234550125674209 0.0299999999999998"
        rpy="0 0 0" />
      <mass
        value="0.0968618745655006" />
      <inertia
        ixx="1.57938620308466E-05"
        ixy="-3.85313324646932E-11"
        ixz="2.28782652934824E-13"
        iyy="2.64453255590243E-06"
        iyz="-1.98004468484315E-20"
        izz="1.31493294752776E-05" />
    </inertial>
    <visual>
      <origin
        xyz="0 0 0"
        rpy="0 0 0" />
      <geometry>
        <mesh
          filename="package://model8/meshes/M7.STL" />
      </geometry>
      <material
        name="">
        <color
          rgba="0.752941176470588 0.752941176470588 0.752941176470588 1" />
      </material>
    </visual>
    <collision>
      <origin
        xyz="0 0 0"
        rpy="0 0 0" />
      <geometry>
        <mesh
          filename="package://model8/meshes/M7.STL" />
      </geometry>
    </collision>
  </link>
  <joint
    name="J7"
    type="revolute">
    <origin
      xyz="0 0.082647 0"
      rpy="9.0749E-17 -9.4058E-16 -6.3039E-17" />
    <parent
      link="M6" />
    <child
      link="M7" />
    <axis
      xyz="0 0 1" />
    <limit
      lower="-1.571"
      upper="1.571"
      effort="0"
      velocity="0" />
  </joint>
  <link
    name="M8">
    <inertial>
      <origin
        xyz="-2.90113098960765E-08 0.0234550125674209 0.0299999999999998"
        rpy="0 0 0" />
      <mass
        value="0.0968618745655005" />
      <inertia
        ixx="1.57938620308465E-05"
        ixy="-3.85313324738181E-11"
        ixz="2.28782652813436E-13"
        iyy="2.64453255590242E-06"
        iyz="-2.3082325678601E-20"
        izz="1.31493294752775E-05" />
    </inertial>
    <visual>
      <origin
        xyz="0 0 0"
        rpy="0 0 0" />
      <geometry>
        <mesh
          filename="package://model8/meshes/M8.STL" />
      </geometry>
      <material
        name="">
        <color
          rgba="0.752941176470588 0.752941176470588 0.752941176470588 1" />
      </material>
    </visual>
    <collision>
      <origin
        xyz="0 0 0"
        rpy="0 0 0" />
      <geometry>
        <mesh
          filename="package://model8/meshes/M8.STL" />
      </geometry>
    </collision>
  </link>
  <joint
    name="J8"
    type="revolute">
    <origin
      xyz="0 0.082647 0"
      rpy="9.0749E-17 4.472E-16 -1.1846E-16" />
    <parent
      link="M7" />
    <child
      link="M8" />
    <axis
      xyz="0 0 1" />
    <limit
      lower="-1.571"
      upper="1.571"
      effort="0"
      velocity="0" />
  </joint>
  <link
    name="M9">
    <inertial>
      <origin
        xyz="-2.90113098821987E-08 0.023455012567423 0.0300000000000005"
        rpy="0 0 0" />
      <mass
        value="0.0968618745655031" />
      <inertia
        ixx="1.57938620308586E-05"
        ixy="-3.85313325695201E-11"
        ixz="2.28782587419749E-13"
        iyy="2.64453255590371E-06"
        iyz="-4.62194143310683E-18"
        izz="1.31493294752883E-05" />
    </inertial>
    <visual>
      <origin
        xyz="0 0 0"
        rpy="0 0 0" />
      <geometry>
        <mesh
          filename="package://model8/meshes/M9.STL" />
      </geometry>
      <material
        name="">
        <color
          rgba="0.752941176470588 0.752941176470588 0.752941176470588 1" />
      </material>
    </visual>
    <collision>
      <origin
        xyz="0 0 0"
        rpy="0 0 0" />
      <geometry>
        <mesh
          filename="package://model8/meshes/M9.STL" />
      </geometry>
    </collision>
  </link>
  <joint
    name="J9"
    type="revolute">
    <origin
      xyz="0 0.082647 0"
      rpy="9.0749E-17 -2.4669E-16 -9.0749E-17" />
    <parent
      link="M8" />
    <child
      link="M9" />
    <axis
      xyz="0 0 1" />
    <limit
      lower="-1.571"
      upper="1.571"
      effort="0"
      velocity="0" />
  </joint>
  <link
    name="Tail">
    <inertial>
      <origin
        xyz="2.19220222252847E-08 0.0264689131835962 0.0299999999999998"
        rpy="0 0 0" />
      <mass
        value="0.128185704647389" />
      <inertia
        ixx="1.18366985416202E-05"
        ixy="4.70006640450819E-11"
        ixz="6.1922860683803E-31"
        iyy="1.86628257272174E-16"
        iyz="-1.55948625896089E-25"
        izz="1.18366985418068E-05" />
    </inertial>
    <visual>
      <origin
        xyz="0 0 0"
        rpy="0 0 0" />
      <geometry>
        <mesh
          filename="package://model8/meshes/Tail.STL" />
      </geometry>
      <material
        name="">
        <color
          rgba="0.752941176470588 0.752941176470588 0.752941176470588 1" />
      </material>
    </visual>
    <collision>
      <origin
        xyz="0 0 0"
        rpy="0 0 0" />
      <geometry>
        <mesh
          filename="package://model8/meshes/Tail.STL" />
      </geometry>
    </collision>
  </link>
  <joint
    name="J10"
    type="revolute">
    <origin
      xyz="0 0.082647 0"
      rpy="9.0749E-17 -3.6655E-16 1.1208E-16" />
    <parent
      link="M9" />
    <child
      link="Tail" />
    <axis
      xyz="0 0 1" />
    <limit
      lower="-1.571"
      upper="1.571"
      effort="0"
      velocity="0" />
  </joint>
</robot>